<?xml version="1.0"?>
<robot name="three_dof_robot">
  <!-- Base Link -->
  <link name="base_link">
    <visual>
      <geometry>
        <box size="0.1 0.1 0.1"/>
      </geometry>
    </visual>
  </link>

  <!-- Link 1 -->
  <link name="link1">
    <visual>
      <geometry>
        <cylinder length="0.5" radius="0.05"/>
      </geometry>
    </visual>
  </link>

  <!-- Link 2 -->
  <link name="link2">
    <visual>
      <geometry>
        <cylinder length="0.5" radius="0.05"/>
      </geometry>
    </visual>
  </link>

  <!-- Link 3 (End Effector) -->
  <link name="link3">
    <visual>
      <geometry>
        <sphere radius="0.1"/>
      </geometry>
    </visual>
  </link>

  <!-- Joints -->
  <joint name="joint1" type="revolute">
    <parent link="base_link"/>
    <child link="link1"/>
    <axis xyz="0 0 1"/>
    <origin xyz="0 0 0.1" rpy="0 0 0"/>
    <limit lower="-1.57" upper="1.57" effort="10" velocity="0.5"/>
  </joint>

  <joint name="joint2" type="revolute">
    <parent link="link1"/>
    <child link="link2"/>
    <axis xyz="0 0 1"/>
    <origin xyz="0 0 0.5" rpy="0 0 0"/>
    <limit lower="-1.57" upper="1.57" effort="10" velocity="0.5"/>
  </joint>

  <joint name="joint3" type="revolute">
    <parent link="link2"/>
    <child link="link3"/>
    <axis xyz="0 0 1"/>
    <origin xyz="0 0 0.5" rpy="0 0 0"/>
    <limit lower="-1.57" upper="1.57" effort="10" velocity="0.5"/>
  </joint>
</robot>
